<?xml version="1.0"?>
<robot xmlns:xacro="http://www.ros.org/wiki/xacro" name="reflex_hand">

  <xacro:macro name="base_color">
    <color rgba="0.1 0.1 0.1 1"/>
  </xacro:macro>

  <xacro:macro name="swivel_color">
    <color rgba="0.1 0.1 0.1 1"/>
  </xacro:macro>

  <xacro:macro name="proximal_color">
    <color rgba="0.16 0.16 0.16 1"/>
  </xacro:macro>

  <xacro:macro name="distal_color">
    <color rgba="0.16 0.16 0.16 1"/>
  </xacro:macro>

  <xacro:macro name="flex_color">
    <color rgba="0.2 0.2 .2 1"/>
  </xacro:macro>

  <xacro:macro name="pad_color">
    <color rgba="0.106 0.227 0.631 1"/>
  </xacro:macro>

  <xacro:macro name="reflex_hand_model" params="prefix *origin parent">
    <link name="${prefix}palm">
      <visual>
        <geometry>
          <mesh filename="package://reflex_hand_model/meshes/base_link.STL"/>
        </geometry>
        <material name="">
          <xacro:base_color/>
        </material>
      </visual>
      <inertial>
        <origin xyz="0 0 0" rpy="0 0 0"/>
        <mass value="1"/>
        <inertia ixx="0.001" ixy="0.0" ixz="0.0" iyy="0.001" iyz="0.0" izz="0.001" />
      </inertial>
    </link>

    <!-- <a> This is strange: Links for Finger 1 but true! </a>-->
    <link name="${prefix}finger_1_1">
      <visual>
        <geometry>
          <mesh filename="package://reflex_hand_model/meshes/swivel_1.STL"/>
        </geometry>
        <material name="">
          <xacro:swivel_color/>
        </material>
      </visual>
      <inertial>
        <origin xyz="0 0 0" rpy="0 0 0"/>
        <mass value="1"/>
        <inertia ixx="0.001" ixy="0.0" ixz="0.0" iyy="0.001" iyz="0.0" izz="0.001" />
      </inertial>
    </link>

    <link name="${prefix}finger_1_2">
      <visual>
        <geometry>
          <mesh filename="package://reflex_hand_model/meshes/proximal_1.STL"/>
        </geometry>
        <origin xyz="-0.011 0.007 0.011" rpy="3.1459 0 0"/>
        <material name="">
          <xacro:proximal_color/>
        </material>
      </visual>
      <inertial>
        <origin xyz="0 0 0" rpy="0 0 0"/>
        <mass value="1"/>
        <inertia ixx="0.001" ixy="0.0" ixz="0.0" iyy="0.001" iyz="0.0" izz="0.001" />
      </inertial>
    </link>

    <link name="${prefix}finger_1_3">
      <visual>
        <geometry>
          <mesh filename="package://reflex_hand_model/meshes/distal_1.STL"/>
        </geometry>
        <origin xyz="-0.077 0.007 0.007" rpy="3.1459 0 0" />
        <material name="">
          <xacro:distal_color/>
        </material>
      </visual>
      <inertial>
        <origin xyz="0 0 0" rpy="0 0 0"/>
        <mass value="1"/>
        <inertia ixx="0.001" ixy="0.0" ixz="0.0" iyy="0.001" iyz="0.0" izz="0.001" />
      </inertial>
    </link>

    <!-- <a> This is strange: Links for Finger 2 but true! </a>-->
    <link name="${prefix}finger_2_1">
      <visual>
        <geometry>
          <mesh filename="package://reflex_hand_model/meshes/swivel_1.STL"/>
        </geometry>
        <material name="">
          <xacro:swivel_color/>
        </material>
      </visual>
      <inertial>
        <origin xyz="0 0 0" rpy="0 0 0"/>
        <mass value="1"/>
        <inertia ixx="0.001" ixy="0.0" ixz="0.0" iyy="0.001" iyz="0.0" izz="0.001" />
      </inertial>
    </link>

    <link name="${prefix}finger_2_2">
      <visual>
        <geometry>
          <mesh filename="package://reflex_hand_model/meshes/proximal_1.STL"/>
        </geometry>
        <origin xyz="-0.011 0.007 0.011" rpy="3.1459 0 0"/>
        <origin rpy="0 0 0" xyz="0 0 0"/>
        <material name="">
          <xacro:proximal_color/>
        </material>
      </visual>
      <inertial>
        <origin xyz="0 0 0" rpy="0 0 0"/>
        <mass value="1"/>
        <inertia ixx="0.001" ixy="0.0" ixz="0.0" iyy="0.001" iyz="0.0" izz="0.001" />
      </inertial>
    </link>

    <link name="${prefix}finger_2_3">
      <visual>
        <geometry>
          <mesh filename="package://reflex_hand_model/meshes/distal_1.STL"/>
        </geometry>
        <origin xyz="-0.077 0.007 0.006" rpy="3.1459 0 0" />
        <origin rpy="0 0 0" xyz="0 0 0"/>
        <material name="">
          <xacro:distal_color/>
        </material>
      </visual>
      <inertial>
        <origin xyz="0 0 0" rpy="0 0 0"/>
        <mass value="1"/>
        <inertia ixx="0.001" ixy="0.0" ixz="0.0" iyy="0.001" iyz="0.0" izz="0.001" />
      </inertial>
    </link>

    <!-- <a> This is strange: Links for Finger 3 but true! </a>-->
    <link name="${prefix}finger_3_1">
      <visual>
        <geometry>
          <mesh filename="package://reflex_hand_model/meshes/swivel_1.STL"/>
        </geometry>
        <origin xyz="-0.011 0.007 0.011" rpy="3.1459 0 0"/>
        <material name="">
          <xacro:swivel_color/>
        </material>
      </visual>
      <inertial>
        <origin xyz="0 0 0" rpy="0 0 0"/>
        <mass value="1"/>
        <inertia ixx="0.001" ixy="0.0" ixz="0.0" iyy="0.001" iyz="0.0" izz="0.001" />
      </inertial>
    </link>

    <link name="${prefix}finger_3_2">
      <visual>
        <geometry>
          <mesh filename="package://reflex_hand_model/meshes/proximal_1.STL"/>
        </geometry>
        <origin xyz="-0.011 0.007 0.011" rpy="3.1459 0 0"/>
        <origin rpy="0 0 0" xyz="0 0 0"/>
        <material name="">
          <xacro:proximal_color/>
        </material>
      </visual>
      <inertial>
        <origin xyz="0 0 0" rpy="0 0 0"/>
        <mass value="1"/>
        <inertia ixx="0.001" ixy="0.0" ixz="0.0" iyy="0.001" iyz="0.0" izz="0.001" />
      </inertial>
    </link>

    <link name="${prefix}finger_3_3">
      <visual>
        <geometry>
          <mesh filename="package://reflex_hand_model/meshes/distal_1.STL"/>
        </geometry>
        <origin xyz="-0.077 0.007 0.006" rpy="3.1459 0 0" />
        <origin rpy="0 0 0" xyz="0 0 0"/>
        <material name="">
          <xacro:distal_color/>
        </material>
      </visual>
      <inertial>
        <origin xyz="0 0 0" rpy="0 0 0"/>
        <mass value="1"/>
        <inertia ixx="0.001" ixy="0.0" ixz="0.0" iyy="0.001" iyz="0.0" izz="0.001" />
      </inertial>
    </link>


    <joint name="${prefix}fixed" type="fixed">
      <insert_block name="origin"/>
      <parent link="${parent}"/>
      <child link="${prefix}palm"/>
    </joint>

    <joint name="${prefix}palm_to_finger_1_1" type="revolute">
      <parent link="${prefix}palm"/>
      <child link="${prefix}finger_1_1"/>
      <limit effort="1000.0" lower="-2.0" upper="0.25" velocity="0.5"/>
      <axis xyz="0 0 -1"/>
      <origin xyz="0.0503973683071414 -0.026 0.063" rpy="6.75550818663469E-16 1.97993848419069E-16 -2.77555756156289E-16" />
    </joint>

    <joint name="${prefix}finger_1_1_to_finger_1_2" type="revolute">
      <parent link="${prefix}finger_1_1"/>
      <child link="${prefix}finger_1_2"/>
      <limit effort="1000.0" lower="-0.1" upper="3.0" velocity="0.5"/>
      <axis xyz="0 -1 0"/>
      <origin xyz="0.01 0 0.0186" rpy="-6.20039667432211E-16 0.28 2.22044604925031E-16" />
    </joint>

    <joint name="${prefix}finger_1_2_to_finger_1_3" type="revolute">
      <parent link="${prefix}finger_1_2"/>
      <child link="${prefix}finger_1_3"/>
      <limit effort="1000.0" lower="0.0" upper="0.548" velocity="0.5"/>
      <axis xyz="0 -1 0"/>
      <origin xyz="0.07600000000000001 0 0.00250000000000002" rpy="0 0 0" />
    </joint>

    <joint name="${prefix}palm_to_finger_2_1" type="revolute">
      <parent link="${prefix}palm"/>
      <child link="${prefix}finger_2_1"/>
      <limit effort="1000.0" lower="-2.0" upper="0.25" velocity="0.5"/>
      <axis xyz="0 0 -1"/>
      <origin xyz="0.0503973683071413 0.0259999999999999 0.063" rpy="1.22459340959228E-15 -7.33448407631817E-16 -1.66533453693773E-16" />
      <mimic joint="palm_to_finger_1_1" multiplier="-1"/>
    </joint>

    <joint name="${prefix}finger_2_1_to_finger_2_2" type="revolute">
      <parent link="${prefix}finger_2_1"/>
      <child link="${prefix}finger_2_2"/>
      <axis xyz="0 -1 0"/>
      <limit effort="1000.0" lower="-0.1" upper="3.0" velocity="0.5"/>
      <origin xyz="0.01 0 0.0186" rpy="-1.16908225836102E-15 0.28 1.11022302462515E-16" />
    </joint>

    <joint name="${prefix}finger_2_2_to_finger_2_3" type="revolute">
      <parent link="${prefix}finger_2_2"/>
      <child link="${prefix}finger_2_3"/>
      <axis xyz="0 -1 0"/>
      <limit effort="1000.0" lower="0.0" upper="0.548" velocity="0.5"/>
      <origin xyz="0.0760000000000001 0 0.00249999999999997" rpy="0 0 0" />
      <origin xyz="0 2 0"/>
    </joint>

    <joint name="${prefix}palm_to_finger_3_1" type="revolute">
      <parent link="${prefix}palm"/>
      <child link="${prefix}finger_3_1"/>
      <axis xyz="0 0 -1"/>
      <limit effort="1000.0" lower="-2.0" upper="2.0" velocity="0.5"/>
      <origin xyz="0 0 0" rpy="0 0 0"/>
      <origin xyz="0 -1.25 0.75"/>
    </joint>

    <joint name="${prefix}finger_3_1_to_finger_3_2" type="revolute">
      <parent link="${prefix}finger_3_1"/>
      <child link="${prefix}finger_3_2"/>
      <axis xyz="0 -1 0"/>
      <limit effort="1000.0" lower="-0.1" upper="3.0" velocity="0.5"/>
      <origin xyz="-0.0299999999999996 0 0.0816000000000002" rpy="-5.55111512312578E-17 0.28 3.14159265358979" />
      <origin xyz="0 0 0.5"/>
    </joint>

    <joint name="${prefix}finger_3_2_to_finger_3_3" type="revolute">
      <parent link="${prefix}finger_3_2"/>
      <child link="${prefix}finger_3_3"/>
      <axis xyz="0 -1 0"/>
      <limit effort="1000.0" lower="0.0" upper="0.548" velocity="0.5"/>
      <origin xyz="0.0760000000000001 0 0.0025" rpy="-1.48887961834512E-45 -1.0995850059156E-76 -7.38531841236285E-32" />
      <origin xyz="0 -2 0"/>
    </joint>

    <!-- This block connects the head_swivel joint to an actuator (motor), which informs both
  simulation and visualization of the robot -->
    <transmission name="${prefix}finger1_1_trans" type="SimpleTransmission">
      <type>transmission_interface/SimpleTransmission</type>
      <actuator name="${prefix}finger11_motor">
        <mechanicalReduction>1</mechanicalReduction>
      </actuator>
      <joint name="${prefix}palm_to_finger_1_1">
        <hardwareInterface>hardware_interface/PositionJointInterface</hardwareInterface>
      </joint>
    </transmission>

    <transmission name="${prefix}finger1_2_trans" type="SimpleTransmission">
      <type>transmission_interface/SimpleTransmission</type>
      <actuator name="${prefix}finger12_motor">
        <mechanicalReduction>1</mechanicalReduction>
      </actuator>
      <joint name="${prefix}finger_1_1_to_finger_1_2">
        <hardwareInterface>hardware_interface/PositionJointInterface</hardwareInterface>
      </joint>
    </transmission>

    <transmission name="${prefix}finger1_3_trans" type="SimpleTransmission">
      <type>transmission_interface/SimpleTransmission</type>
      <actuator name="${prefix}finger13_motor">
        <mechanicalReduction>1</mechanicalReduction>
      </actuator>
      <joint name="${prefix}finger_1_2_to_finger_1_3">
        <hardwareInterface>hardware_interface/PositionJointInterface</hardwareInterface>
      </joint>
    </transmission>

    <transmission name="${prefix}finger2_1_trans" type="SimpleTransmission">
      <type>transmission_interface/SimpleTransmission</type>
      <actuator name="${prefix}finger21_motor">
        <mechanicalReduction>1</mechanicalReduction>
      </actuator>
      <joint name="${prefix}palm_to_finger_2_1">
        <hardwareInterface>hardware_interface/PositionJointInterface</hardwareInterface>
      </joint>
    </transmission>

    <transmission name="${prefix}finger2_2_trans" type="SimpleTransmission">
      <type>transmission_interface/SimpleTransmission</type>
      <actuator name="${prefix}finger22_motor">
        <mechanicalReduction>1</mechanicalReduction>
      </actuator>
      <joint name="${prefix}finger_2_1_to_finger_2_2">
        <hardwareInterface>hardware_interface/PositionJointInterface</hardwareInterface>
      </joint>
    </transmission>

    <transmission name="${prefix}finger2_3_trans" type="SimpleTransmission">
      <type>transmission_interface/SimpleTransmission</type>
      <actuator name="${prefix}finger23_motor">
        <mechanicalReduction>1</mechanicalReduction>
      </actuator>
      <joint name="${prefix}finger_2_2_to_finger_2_3">
        <hardwareInterface>hardware_interface/PositionJointInterface</hardwareInterface>
      </joint>
    </transmission>

    <transmission name="${prefix}finger3_1_trans" type="SimpleTransmission">
      <type>transmission_interface/SimpleTransmission</type>
      <actuator name="${prefix}finger31_motor">
        <mechanicalReduction>1</mechanicalReduction>
      </actuator>
      <joint name="${prefix}palm_to_finger_3_1">
        <hardwareInterface>hardware_interface/PositionJointInterface</hardwareInterface>
      </joint>
    </transmission>

    <transmission name="${prefix}finger2_3_trans" type="SimpleTransmission">
      <type>transmission_interface/SimpleTransmission</type>
      <actuator name="${prefix}finger32_motor">
        <mechanicalReduction>1</mechanicalReduction>
      </actuator>
      <joint name="${prefix}finger_3_1_to_finger_3_2">
        <hardwareInterface>hardware_interface/PositionJointInterface</hardwareInterface>
      </joint>
    </transmission>

    <transmission name="${prefix}finger3_3_trans" type="SimpleTransmission">
      <type>transmission_interface/SimpleTransmission</type>
      <actuator name="${prefix}finger33_motor">
        <mechanicalReduction>1</mechanicalReduction>
      </actuator>
      <joint name="${prefix}finger_3_2_to_finger_3_3">
        <hardwareInterface>hardware_interface/PositionJointInterface</hardwareInterface>
      </joint>
    </transmission>

  </xacro:macro>



</robot>